<mujoco model="b2">
  <compiler angle="radian" meshdir="../meshes" autolimits="true"/>

  <default>
    <default class="b2">
      <geom type="mesh"/>
      <joint damping="1" armature="0.1"/>
      <default class="visual">
        <geom contype="0" conaffinity="0" group="2"/>
      </default>
      <default class="collision">
        <geom group="3" mass="0" density="0"/>
      </default>
      <site size="0.001" rgba="0.5 0.5 0.5 0.3" group="4"/>
    </default>
  </default>

  <asset>
    <mesh name="collaborative_arm_base" file="collaborative_arm_base_reset.stl" scale="0.025 0.025 0.025"/>
    <mesh name="gimbal" file="gimbal_reset.stl" scale="0.025 0.025 0.025"/>
    <mesh name="base_link" file="base_link.obj"/>
    <mesh name="logo_left" file="logo_left.obj"/>
    <mesh name="logo_right" file="logo_right.obj"/>
    <mesh name="unitree_ladar" file="unitree_ladar.obj"/>
    <mesh name="f_dc_link" file="f_dc_link.obj"/>
    <mesh name="r_dc_link" file="r_dc_link.obj"/>
    <mesh name="fake_imu_link" file="fake_imu_link.STL"/>
    <mesh name="fake_head_Link" file="fake_head_Link.STL"/>
    <mesh name="fake_tail_link" file="fake_tail_link.STL"/>
    <mesh name="FL_hip" file="FL_hip.obj"/>
    <mesh name="FL_thigh" file="FL_thigh.obj"/>
    <mesh name="FL_thigh_protect" file="FL_thigh_protect.obj"/>
    <mesh name="FL_calf" file="FL_calf.obj"/>
    <mesh name="FL_foot" file="FL_foot.obj"/>
    <mesh name="FR_hip" file="FR_hip.obj"/>
    <mesh name="FR_thigh" file="FR_thigh.obj"/>
    <mesh name="FR_thigh_protect" file="FR_thigh_protect.obj"/>
    <mesh name="FR_calf" file="FR_calf.obj"/>
    <mesh name="FR_foot" file="FR_foot.obj"/>
    <mesh name="RL_hip" file="RL_hip.obj"/>
    <mesh name="RL_thigh" file="RL_thigh.obj"/>
    <mesh name="RL_thigh_protect" file="RL_thigh_protect.obj"/>
    <mesh name="RL_calf" file="RL_calf.obj"/>
    <mesh name="RL_foot" file="RL_foot.obj"/>
    <mesh name="RR_hip" file="RR_hip.obj"/>
    <mesh name="RR_thigh" file="RR_thigh.obj"/>
    <mesh name="RR_thigh_protect" file="RR_thigh_protect.obj"/>
    <mesh name="RR_calf" file="RR_calf.obj"/>
    <mesh name="RR_foot" file="RR_foot.obj"/>
    <mesh name="f_oc_link" file="f_oc_link.obj"/>
    <mesh name="r_oc_link" file="r_oc_link.obj"/>
    <mesh name="arm_base_link" file="arm_base_link.STL"/>
    <mesh name="link1" file="link1.STL"/>
    <mesh name="link2" file="link2.STL"/>
    <mesh name="link3" file="link3.STL"/>
    <mesh name="link4" file="link4.STL"/>
    <mesh name="link5" file="link5.STL"/>
    <mesh name="link6" file="link6.STL"/>

  </asset>
  <worldbody>
    <body name="base_link" pos="0 0 0.8" childclass="b2">
      <inertial pos="0.0212868 0.0045819 0.0106169" quat="0.00178111 0.675412 -0.000262894 0.737438" mass="35.86" diaginertia="1.73786 1.66448 0.343734"/>
      <joint name="floating_base_joint" type="free"/>
      <geom type="mesh" contype="0" conaffinity="0" group="1" density="0" rgba="0.7 0.7 0.7 1" mesh="base_link"/>
      <geom size="0.25 0.14 0.075" type="box" rgba="0.7 0.7 0.7 1" class="collision"/>
      <geom type="mesh" contype="0" conaffinity="0" group="1" density="0" rgba="1 1 1 1" mesh="logo_left"/>
      <geom type="mesh" contype="0" conaffinity="0" group="1" density="0" rgba="1 1 1 1" mesh="logo_right"/>
      <geom pos="0.34218 0 0.17851" type="mesh" contype="0" conaffinity="0" group="1" density="0" rgba="0.15 0.15 0.15 1" mesh="unitree_ladar"/>
      <geom size="0.076 0.08" pos="0.34218 0 0.15851" type="cylinder" rgba="0.15 0.15 0.15 1" class="collision"/>
      <geom pos="0.841724 -4.57659e-06 0.130379" quat="0.00244632 3.13845e-06 0.999997 1.29099e-06" type="mesh" contype="0" conaffinity="0" group="1" density="0" rgba="0 0 0 1" mesh="f_dc_link"/>
      <geom pos="-0.378319 0.000200109 -0.379902" quat="-1.30076e-06 -0.708662 5.35065e-07 0.705548" type="mesh" contype="0" conaffinity="0" group="1" density="0" rgba="0 0 0 1" mesh="r_dc_link"/>
      <geom pos="0 -0.02341 0.04927" type="mesh" contype="0" conaffinity="0" group="1" density="0" rgba="0 0 0 1" mesh="fake_imu_link"/>
      <geom type="mesh" contype="0" conaffinity="0" group="1" density="0" rgba="0 0 0 1" mesh="fake_head_Link"/>
      <geom size="0.02 0.06 0.07" pos="0.41 0 0.005" type="box" rgba="0 0 0 1" class="collision"/>
      <geom type="mesh" contype="0" conaffinity="0" group="1" density="0" rgba="0 0 0 1" mesh="fake_tail_link"/>
      <geom size="0.0125 0.06 0.07" pos="-0.405 0 0.005" type="box" rgba="0 0 0 1" class="collision"/>
      <geom pos="0.84158 -0.0134347 -0.0134347" quat="-3.89602e-06 1.29867e-06 0.707107 -0.707107" type="mesh" contype="0" conaffinity="0" group="1" density="0" rgba="0 0 0 1" mesh="f_oc_link"/>
      <geom pos="-0.00451008 0.0252504 -0.0262476" quat="0.707107 -0.707107 -1.29867e-06 -1.29867e-06" type="mesh" contype="0" conaffinity="0" group="1" density="0" rgba="0 0 0 1" mesh="r_oc_link"/>
      <site name="imu" pos="0 -0.02341 0.04927"/>

      <body name="FL_hip" pos="0.3285 0.072 0">
        <inertial pos="-0.00348459 -0.00896704 0" quat="0.511347 0.510967 0.488412 0.488763" mass="2.9464" diaginertia="0.00502561 0.00397571 0.00346037"/>
        <joint name="FL_hip_joint" pos="0 0 0" axis="1 0 0" range="-0.87 0.87"/>
        <geom type="mesh" contype="0" conaffinity="0" group="1" density="0" rgba="0.7 0.7 0.7 1" mesh="FL_hip"/>
        <geom size="0.07 0.025" pos="0 0.12 0" quat="0.707107 0.707107 0 0" type="cylinder" rgba="0.7 0.7 0.7 1" class="collision"/>
        <body name="FL_thigh" pos="0 0.11973 0">
          <inertial pos="-0.00592206 -0.0335174 -0.0545473" quat="0.910035 0.0855949 -0.000888135 0.405597" mass="4.8094" diaginertia="0.0640934 0.0634463 0.00699942"/>
          <joint name="FL_thigh_joint" pos="0 0 0" axis="0 1 0" range="-0.94 4.69"/>
          <geom type="mesh" contype="0" conaffinity="0" group="1" density="0" rgba="0.7 0.7 0.7 1" mesh="FL_thigh"/>
          <geom size="0.16 0.02225 0.027" pos="-0.025 0 -0.16" quat="0.707388 0 0.706825 0" type="box" rgba="0.7 0.7 0.7 1" class="collision"/>
          <geom type="mesh" contype="0" conaffinity="0" group="1" density="0" rgba="0.65 0.68 0.65 1" mesh="FL_thigh_protect"/>
          <body name="FL_calf" pos="0 -8.6984e-05 -0.35">
            <inertial pos="0.00792095 0 -0.180895" quat="0.70709 -0.00488772 -0.00488772 0.70709" mass="0.53" diaginertia="0.0169205 0.0167822 0.000404298"/>
            <joint name="FL_calf_joint" pos="0 0 0" axis="0 1 0" range="-2.82 -0.43"/>
            <geom type="mesh" contype="0" conaffinity="0" group="1" density="0" rgba="0.7 0.7 0.7 1" mesh="FL_calf"/>
            <geom size="0.05 0.01225 0.009" pos="-0.002 0 -0.03" quat="0.825336 0 0.564642 0" type="box" rgba="0.7 0.7 0.7 1" class="collision"/>
            <geom size="0.05 0.01225 0.009" pos="0.022 0 -0.1" quat="0.780707 0 0.624897 0" type="box" rgba="0.7 0.7 0.7 1" class="collision"/>
            <geom size="0.075 0.01225 0.0075" pos="0.036 0 -0.225" quat="0.721382 0 0.692537 0" type="box" rgba="0.7 0.7 0.7 1" class="collision"/>
            <geom size="0.025 0.014 0.0175" pos="0.023 0 -0.31" quat="0.540302 0 0.841471 0" type="box" rgba="0.7 0.7 0.7 1" class="collision"/>
            <geom pos="0 8.6986e-05 0" type="mesh" contype="0" conaffinity="0" group="1" density="0" rgba="0.15 0.15 0.15 1" mesh="FL_foot" friction="0.4 0.005 0.0001"/>
            <geom size="0.032" pos="0 8.6986e-05 -0.35" quat="0.707388 0.706825 0 0" type="sphere" rgba="0.15 0.15 0.15 1" class="collision" friction="0.4 0.005 0.0001"/>
          </body>
        </body>
      </body>
      <body name="FR_hip" pos="0.3285 -0.072 0">
        <inertial pos="-0.00844158 0.0100194 0.000239503" quat="0.476608 0.477229 0.518954 0.525151" mass="2.9464" diaginertia="0.00485575 0.00370656 0.00277186"/>
        <joint name="FR_hip_joint" pos="0 0 0" axis="1 0 0" range="-0.87 0.87"/>
        <geom type="mesh" contype="0" conaffinity="0" group="1" density="0" rgba="0.7 0.7 0.7 1" mesh="FR_hip"/>
        <geom size="0.07 0.025" pos="0 -0.12 0" quat="0.707107 0.707107 0 0" type="cylinder" rgba="0.7 0.7 0.7 1" class="collision"/>
        <body name="FR_thigh" pos="0 -0.11973 0">
          <inertial pos="-0.00592206 0.0335174 -0.0545473" quat="0.40566 -0.000894103 0.0855942 0.910007" mass="4.8094" diaginertia="0.0640936 0.0634464 0.00699948"/>
          <joint name="FR_thigh_joint" pos="0 0 0" axis="0 1 0" range="-0.94 4.69"/>
          <geom type="mesh" contype="0" conaffinity="0" group="1" density="0" rgba="0.7 0.7 0.7 1" mesh="FR_thigh"/>
          <geom size="0.125 0.014 0.02" pos="-0.03 0 -0.2" quat="0.707388 0 0.706825 0" type="box" rgba="0.7 0.7 0.7 1" class="collision"/>
          <geom type="mesh" contype="0" conaffinity="0" group="1" density="0" rgba="0.65 0.68 0.65 1" mesh="FR_thigh_protect"/>
          <body name="FR_calf" pos="0 8.6986e-05 -0.35">
            <inertial pos="0.00792095 0 -0.180895" quat="0.70709 -0.00488772 -0.00488772 0.70709" mass="0.53" diaginertia="0.0169205 0.0167822 0.000404298"/>
            <joint name="FR_calf_joint" pos="0 0 0" axis="0 1 0" range="-2.82 -0.43"/>
            <geom type="mesh" contype="0" conaffinity="0" group="1" density="0" rgba="0.7 0.7 0.7 1" mesh="FR_calf"/>
            <geom size="0.05 0.01225 0.009" pos="-0.002 0 -0.03" quat="0.825336 0 0.564642 0" type="box" rgba="0.7 0.7 0.7 1" class="collision"/>
            <geom size="0.05 0.01225 0.009" pos="0.022 0 -0.1" quat="0.780707 0 0.624897 0" type="box" rgba="0.7 0.7 0.7 1" class="collision"/>
            <geom size="0.075 0.01225 0.0075" pos="0.036 0 -0.225" quat="0.721382 0 0.692537 0" type="box" rgba="0.7 0.7 0.7 1" class="collision"/>
            <geom size="0.025 0.014 0.0175" pos="0.023 0 -0.31" quat="0.540302 0 0.841471 0" type="box" rgba="0.7 0.7 0.7 1" class="collision"/>
            <geom type="mesh" contype="0" conaffinity="0" group="1" density="0" rgba="0.15 0.15 0.15 1" mesh="FR_foot" friction="0.4 0.005 0.0001"/>
            <geom size="0.032" pos="0 8.6986e-05 -0.35" quat="0.707388 0.706825 0 0" type="sphere" rgba="0.15 0.15 0.15 1" class="collision" friction="0.4 0.005 0.0001"/>
          </body>
        </body>
      </body>
      <body name="RL_hip" pos="-0.3285 0.072 0">
        <inertial pos="0.00844158 -0.0100194 0.000239503" quat="0.477229 0.476608 0.525151 0.518954" mass="2.9464" diaginertia="0.00485575 0.00370656 0.00277186"/>
        <joint name="RL_hip_joint" pos="0 0 0" axis="1 0 0" range="-0.87 0.87"/>
        <geom type="mesh" contype="0" conaffinity="0" group="1" density="0" rgba="0.7 0.7 0.7 1" mesh="RL_hip"/>
        <geom size="0.07 0.025" pos="0 0.12 0" quat="0.707107 0.707107 0 0" type="cylinder" rgba="0.7 0.7 0.7 1" class="collision"/>
        <body name="RL_thigh" pos="0 0.11973 0">
          <inertial pos="-0.00592206 -0.0335174 -0.0545473" quat="0.910007 0.0855942 -0.000894103 0.40566" mass="4.8094" diaginertia="0.0640936 0.0634464 0.00699948"/>
          <joint name="RL_thigh_joint" pos="0 0 0" axis="0 1 0" range="-0.94 4.69"/>
          <geom type="mesh" contype="0" conaffinity="0" group="1" density="0" rgba="0.7 0.7 0.7 1" mesh="RL_thigh"/>
          <geom size="0.125 0.014 0.02" pos="-0.03 0 -0.2" quat="0.707388 0 0.706825 0" type="box" rgba="0.7 0.7 0.7 1" class="collision"/>
          <geom type="mesh" contype="0" conaffinity="0" group="1" density="0" rgba="0.65 0.68 0.65 1" mesh="RL_thigh_protect"/>
          <body name="RL_calf" pos="0 -8.6984e-05 -0.35">
            <inertial pos="0.00792095 0 -0.180895" quat="0.70709 -0.00488772 -0.00488772 0.70709" mass="0.53" diaginertia="0.0169205 0.0167822 0.000404298"/>
            <joint name="RL_calf_joint" pos="0 0 0" axis="0 1 0" range="-2.82 -0.43"/>
            <geom type="mesh" contype="0" conaffinity="0" group="1" density="0" rgba="0.7 0.7 0.7 1" mesh="RL_calf"/>
            <geom size="0.05 0.01225 0.009" pos="-0.002 0 -0.03" quat="0.825336 0 0.564642 0" type="box" rgba="0.7 0.7 0.7 1" class="collision"/>
            <geom size="0.05 0.01225 0.009" pos="0.022 0 -0.1" quat="0.780707 0 0.624897 0" type="box" rgba="0.7 0.7 0.7 1" class="collision"/>
            <geom size="0.075 0.01225 0.0075" pos="0.036 0 -0.225" quat="0.721382 0 0.692537 0" type="box" rgba="0.7 0.7 0.7 1" class="collision"/>
            <geom size="0.025 0.014 0.0175" pos="0.023 0 -0.31" quat="0.540302 0 0.841471 0" type="box" rgba="0.7 0.7 0.7 1" class="collision"/>
            <geom pos="0 8.6986e-05 0" type="mesh" contype="0" conaffinity="0" group="1" density="0" rgba="0.15 0.15 0.15 1" mesh="RL_foot" friction="0.4 0.005 0.0001"/>
            <geom size="0.032" pos="0 8.6986e-05 -0.35" quat="0.707388 0.706825 0 0" type="sphere" rgba="0.15 0.15 0.15 1" class="collision" friction="0.4 0.005 0.0001"/>
          </body>
        </body>
      </body>
      <body name="RR_hip" pos="-0.3285 -0.072 0">
        <inertial pos="0.00348459 0.00896704 0" quat="0.510967 0.511347 0.488763 0.488412" mass="2.9464" diaginertia="0.00502561 0.00397571 0.00346037"/>
        <joint name="RR_hip_joint" pos="0 0 0" axis="1 0 0" range="-0.87 0.87"/>
        <geom type="mesh" contype="0" conaffinity="0" group="1" density="0" rgba="0.7 0.7 0.7 1" mesh="RR_hip"/>
        <geom size="0.07 0.025" pos="0 -0.12 0" quat="0.707107 0.707107 0 0" type="cylinder" rgba="0.7 0.7 0.7 1" class="collision"/>
        <body name="RR_thigh" pos="0 -0.11973 0">
          <inertial pos="-0.00592206 0.0335174 -0.0545473" quat="0.405597 -0.000888135 0.0855949 0.910035" mass="4.8094" diaginertia="0.0640934 0.0634463 0.00699942"/>
          <joint name="RR_thigh_joint" pos="0 0 0" axis="0 1 0" range="-0.94 4.69"/>
          <geom type="mesh" contype="0" conaffinity="0" group="1" density="0" rgba="0.7 0.7 0.7 1" mesh="RR_thigh"/>
          <geom size="0.125 0.014 0.02" pos="-0.03 0 -0.2" quat="0.707388 0 0.706825 0" type="box" rgba="0.7 0.7 0.7 1" class="collision"/>
          <geom type="mesh" contype="0" conaffinity="0" group="1" density="0" rgba="0.65 0.68 0.65 1" mesh="RR_thigh_protect"/>
          <body name="RR_calf" pos="0 8.6986e-05 -0.35">
            <inertial pos="0.00792095 0 -0.180895" quat="0.70709 -0.00488772 -0.00488772 0.70709" mass="0.53" diaginertia="0.0169205 0.0167822 0.000404298"/>
            <joint name="RR_calf_joint" pos="0 0 0" axis="0 1 0" range="-2.82 -0.43"/>
            <geom type="mesh" contype="0" conaffinity="0" group="1" density="0" rgba="0.7 0.7 0.7 1" mesh="RR_calf"/>
            <geom size="0.05 0.01225 0.009" pos="-0.002 0 -0.03" quat="0.825336 0 0.564642 0" type="box" rgba="0.7 0.7 0.7 1" class="collision"/>
            <geom size="0.05 0.01225 0.009" pos="0.022 0 -0.1" quat="0.780707 0 0.624897 0" type="box" rgba="0.7 0.7 0.7 1" class="collision"/>
            <geom size="0.075 0.01225 0.0075" pos="0.036 0 -0.225" quat="0.721382 0 0.692537 0" type="box" rgba="0.7 0.7 0.7 1" class="collision"/>
            <geom size="0.025 0.014 0.0175" pos="0.023 0 -0.31" quat="0.540302 0 0.841471 0" type="box" rgba="0.7 0.7 0.7 1" class="collision"/>
            <geom pos="0 -8.6984e-05 0" type="mesh" contype="0" conaffinity="0" group="1" density="0" rgba="0.15 0.15 0.15 1" mesh="RR_foot" friction="0.4 0.005 0.0001"/>
            <geom size="0.032" pos="0 8.6986e-05 -0.35" quat="0.707388 0.706825 0 0" type="sphere" rgba="0.15 0.15 0.15 1" class="collision" friction="0.4 0.005 0.0001"/>
          </body>
        </body>
      </body>
    <body name="rm_arm" pos="-0.026922 0 0.23273">
      <geom type="mesh" contype="0" conaffinity="0" group="1" density="0" rgba="1 1 1 1" mesh="arm_base_link"/>
      <geom type="mesh" rgba="1 1 1 1" mesh="arm_base_link"/>
      <body name="Link1" pos="0 0 0.2405">
        <inertial pos="1.22263e-08 0.021108 -0.0251854" quat="0.988851 -0.148906 -2.80074e-05 -0.000243475" mass="0.593563" diaginertia="0.00126614 0.00124677 0.000496264"/>
        <joint name="joint1" pos="0 0 0" axis="0 0 1" range="-3.1 3.1" actuatorfrcrange="-60 60"/>
        <geom type="mesh" contype="0" conaffinity="0" group="1" density="0" rgba="1 1 1 1" mesh="link1"/>
        <geom type="mesh" rgba="1 1 1 1" mesh="link1"/>
        <body name="Link2" quat="0.499998 0.5 -0.5 0.500002">
          <inertial pos="0.152256 4.75384e-07 -0.0062026" quat="1.2834e-05 0.785787 1.90512e-05 0.618497" mass="0.864175" diaginertia="0.00735632 0.00733754 0.000513875"/>
          <joint name="joint2" pos="0 0 0" axis="0 0 1" range="-2.268 2.268" actuatorfrcrange="-60 60"/>
          <geom type="mesh" contype="0" conaffinity="0" group="1" density="0" rgba="1 1 1 1" mesh="link2"/>
          <geom type="mesh" rgba="1 1 1 1" mesh="link2"/>
          <body name="Link3" pos="0.256 0 0" quat="0.707105 0 0 0.707108">
            <inertial pos="5.05313e-06 -0.0595926 0.0105691" quat="0.424678 0.56496 -0.565554 0.424992" mass="0.289634" diaginertia="0.00065604 0.000637371 0.000114622"/>
            <joint name="joint3" pos="0 0 0" axis="0 0 1" range="-2.355 2.355" actuatorfrcrange="-30 30"/>
            <geom type="mesh" contype="0" conaffinity="0" group="1" density="0" rgba="1 1 1 1" mesh="link3"/>
            <geom type="mesh" rgba="1 1 1 1" mesh="link3"/>
            <body name="Link4" pos="0 -0.21 0" quat="0.707105 0.707108 0 0">
              <inertial pos="1.15517e-06 -0.0180424 -0.0215395" quat="0.990405 0.138195 -7.01319e-06 0.000110532" mass="0.23942" diaginertia="0.000285939 0.000275318 0.000107298"/>
              <joint name="joint4" pos="0 0 0" axis="0 0 1" range="-3.1 3.1" actuatorfrcrange="-10 10"/>
              <geom type="mesh" contype="0" conaffinity="0" group="1" density="0" rgba="1 1 1 1" mesh="link4"/>
              <geom type="mesh" rgba="1 1 1 1" mesh="link4"/>
              <body name="Link5" quat="0.707105 -0.707108 0 0">
                <inertial pos="3.19795e-06 -0.0593808 0.00736804" quat="0.419765 0.568659 -0.5692 0.420041" mass="0.2188" diaginertia="0.000358615 0.00035054 8.07958e-05"/>
                <joint name="joint5" pos="0 0 0" axis="0 0 1" range="-2.233 2.233" actuatorfrcrange="-10 10"/>
                <geom type="mesh" contype="0" conaffinity="0" group="1" density="0" rgba="1 1 1 1" mesh="link5"/>
                <geom type="mesh" rgba="1 1 1 1" mesh="link5"/>
                <body name="Link6" pos="0 -0.144 0" quat="0.707105 0.707108 0 0">
                  <inertial pos="0.000714235 -0.000396719 -0.0126724" quat="0.613063 0.350717 -0.614301 0.351831" mass="0.0649018" diaginertia="3.17886e-05 2.10548e-05 1.80205e-05"/>
                  <joint name="joint6" pos="0 0 0" axis="0 0 1" range="-6.28 6.28" actuatorfrcrange="-10 10"/>
                  <geom type="mesh" contype="0" conaffinity="0" group="1" density="0" rgba="1 1 1 1" mesh="link6"/>
                  <geom type="mesh" rgba="1 1 1 1" mesh="link6"/>
                </body>
              </body>
            </body>
          </body>
        </body>
      </body>
    </body>
    <geom pos="-0.042093 -0.027237 0.15944" quat="0.707 0 0 0.707" type="mesh" contype="0" conaffinity="0" group="1" density="0" rgba="1 1 1 1" mesh="collaborative_arm_base"/>
    <geom pos="-0.042093 -0.027237 0.15944" quat="0.707 0 0 0.707" type="mesh" mesh="collaborative_arm_base" class="collision"/>
    <geom pos="0.19351 0 0.3098" quat="0.707 0 0 0.707" type="mesh" contype="0" conaffinity="0" group="1" density="0" rgba="1 1 1 1" mesh="gimbal"/>
    <geom pos="0.19351 0 0.3098" quat="0.707 0 0 0.707" type="mesh" mesh="gimbal" class="collision"/>
    </body>
  </worldbody>

  <actuator>
    <motor class="b2" ctrlrange="-200 200"  name="FR_hip" joint="FR_hip_joint"/>
    <motor class="b2" ctrlrange="-200 200"  name="FR_thigh" joint="FR_thigh_joint"/>
    <motor class="b2" ctrlrange="-300 300"  name="FR_calf" joint="FR_calf_joint"/>
    <motor class="b2" ctrlrange="-200 200"  name="FL_hip" joint="FL_hip_joint"/>
    <motor class="b2" ctrlrange="-200 200"  name="FL_thigh" joint="FL_thigh_joint"/>
    <motor class="b2" ctrlrange="-300 300" name="FL_calf" joint="FL_calf_joint"/>
    <motor class="b2" ctrlrange="-200 200"  name="RR_hip" joint="RR_hip_joint"/>
    <motor class="b2" ctrlrange="-200 200"  name="RR_thigh" joint="RR_thigh_joint"/>
    <motor class="b2" ctrlrange="-300 300" name="RR_calf" joint="RR_calf_joint"/>
    <motor class="b2" ctrlrange="-200 200"  name="RL_hip" joint="RL_hip_joint"/>
    <motor class="b2" ctrlrange="-200 200"  name="RL_thigh" joint="RL_thigh_joint"/>
    <motor class="b2" ctrlrange="-300 300" name="RL_calf" joint="RL_calf_joint"/>
    <motor name="joint1_motor" joint="joint1" ctrlrange="-60 60"/>
    <motor name="joint2_motor" joint="joint2" ctrlrange="-60 60"/>
    <motor name="joint3_motor" joint="joint3" ctrlrange="-30 30"/>
    <motor name="joint4_motor" joint="joint4" ctrlrange="-10 10"/>
    <motor name="joint5_motor" joint="joint5" ctrlrange="-10 10"/>
    <motor name="joint6_motor" joint="joint6" ctrlrange="-10 10"/>
  </actuator>

  <sensor>
    <jointpos name="FR_hip_pos" joint="FR_hip_joint" />
    <jointpos name="FR_thigh_pos" joint="FR_thigh_joint" />
    <jointpos name="FR_calf_pos" joint="FR_calf_joint" />
    <jointpos name="FL_hip_pos" joint="FL_hip_joint" />
    <jointpos name="FL_thigh_pos" joint="FL_thigh_joint" />
    <jointpos name="FL_calf_pos" joint="FL_calf_joint" />
    <jointpos name="RR_hip_pos" joint="RR_hip_joint" />
    <jointpos name="RR_thigh_pos" joint="RR_thigh_joint" />
    <jointpos name="RR_calf_pos" joint="RR_calf_joint" />
    <jointpos name="RL_hip_pos" joint="RL_hip_joint" />
    <jointpos name="RL_thigh_pos" joint="RL_thigh_joint" />
    <jointpos name="RL_calf_pos" joint="RL_calf_joint" />

    <jointvel name="FR_hip_vel" joint="FR_hip_joint" />
    <jointvel name="FR_thigh_vel" joint="FR_thigh_joint" />
    <jointvel name="FR_calf_vel" joint="FR_calf_joint" />
    <jointvel name="FL_hip_vel" joint="FL_hip_joint" />
    <jointvel name="FL_thigh_vel" joint="FL_thigh_joint" />
    <jointvel name="FL_calf_vel" joint="FL_calf_joint" />
    <jointvel name="RR_hip_vel" joint="RR_hip_joint" />
    <jointvel name="RR_thigh_vel" joint="RR_thigh_joint" />
    <jointvel name="RR_calf_vel" joint="RR_calf_joint" />
    <jointvel name="RL_hip_vel" joint="RL_hip_joint" />
    <jointvel name="RL_thigh_vel" joint="RL_thigh_joint" />
    <jointvel name="RL_calf_vel" joint="RL_calf_joint" />

    <framequat name="body_quat" objtype="site" objname="imu" />
    <gyro name="body_gyro" site="imu" />
    <accelerometer name="body_acc" site="imu" />
    <framepos name="body_pos" objtype="site" objname="imu" />

    <jointpos name="joint1_pos" joint="joint1"/>
    <jointpos name="joint2_pos" joint="joint2"/>
    <jointpos name="joint3_pos" joint="joint3"/>
    <jointpos name="joint4_pos" joint="joint4"/>
    <jointpos name="joint5_pos" joint="joint5"/>
    <jointpos name="joint6_pos" joint="joint6"/>
    <jointvel name="joint1_vel" joint="joint1"/>
    <jointvel name="joint2_vel" joint="joint2"/>
    <jointvel name="joint3_vel" joint="joint3"/>
    <jointvel name="joint4_vel" joint="joint4"/>
    <jointvel name="joint5_vel" joint="joint5"/>
    <jointvel name="joint6_vel" joint="joint6"/>
  </sensor>

  <!-- <keyframe>
    <key name="home" qpos="0 0 0.5 1 0 0 0 0 1.28 -2.84 0 1.28 -2.84 0 1.28 -2.84 0 1.28 -2.84"
      ctrl="0 1.28 -2.84 0 1.28 -2.84 0 1.28 -2.84 0 1.28 -2.84"/>
  </keyframe> -->

</mujoco>
